[2025-09-10T07:31:38.781+0000] {taskinstance.py:1083} INFO - Dependencies all met for <TaskInstance: csv_validation_pipeline_v1.load_path_task manual__2025-09-10T07:26:34.784837+00:00 [queued]>
[2025-09-10T07:31:38.791+0000] {taskinstance.py:1083} INFO - Dependencies all met for <TaskInstance: csv_validation_pipeline_v1.load_path_task manual__2025-09-10T07:26:34.784837+00:00 [queued]>
[2025-09-10T07:31:38.791+0000] {taskinstance.py:1279} INFO - 
--------------------------------------------------------------------------------
[2025-09-10T07:31:38.791+0000] {taskinstance.py:1280} INFO - Starting attempt 2 of 2
[2025-09-10T07:31:38.791+0000] {taskinstance.py:1281} INFO - 
--------------------------------------------------------------------------------
[2025-09-10T07:31:38.808+0000] {taskinstance.py:1300} INFO - Executing <Task(PythonOperator): load_path_task> on 2025-09-10 07:26:34.784837+00:00
[2025-09-10T07:31:38.818+0000] {standard_task_runner.py:55} INFO - Started process 616 to run task
[2025-09-10T07:31:38.823+0000] {standard_task_runner.py:82} INFO - Running: ['***', 'tasks', 'run', 'csv_validation_pipeline_v1', 'load_path_task', 'manual__2025-09-10T07:26:34.784837+00:00', '--job-id', '6', '--raw', '--subdir', 'DAGS_FOLDER/flow.py', '--cfg-path', '/tmp/tmpyurjvjv3']
[2025-09-10T07:31:38.824+0000] {standard_task_runner.py:83} INFO - Job 6: Subtask load_path_task
[2025-09-10T07:31:38.911+0000] {task_command.py:388} INFO - Running <TaskInstance: csv_validation_pipeline_v1.load_path_task manual__2025-09-10T07:26:34.784837+00:00 [running]> on host 31c2b52cdb43
[2025-09-10T07:31:39.003+0000] {taskinstance.py:1509} INFO - Exporting the following env vars:
AIRFLOW_CTX_DAG_OWNER=***
AIRFLOW_CTX_DAG_ID=csv_validation_pipeline_v1
AIRFLOW_CTX_TASK_ID=load_path_task
AIRFLOW_CTX_EXECUTION_DATE=2025-09-10T07:26:34.784837+00:00
AIRFLOW_CTX_TRY_NUMBER=2
AIRFLOW_CTX_DAG_RUN_ID=manual__2025-09-10T07:26:34.784837+00:00
[2025-09-10T07:31:39.007+0000] {logging_mixin.py:137} INFO - Checking: /home/jay/login-signup/***_project/uploads/jay.csv
[2025-09-10T07:31:39.007+0000] {logging_mixin.py:137} INFO - Exists? False
[2025-09-10T07:31:39.007+0000] {logging_mixin.py:137} INFO - CSV file not found.
[2025-09-10T07:31:39.007+0000] {taskinstance.py:1768} ERROR - Task failed with exception
Traceback (most recent call last):
  File "/home/airflow/.local/lib/python3.7/site-packages/airflow/operators/python.py", line 175, in execute
    return_value = self.execute_callable()
  File "/home/airflow/.local/lib/python3.7/site-packages/airflow/operators/python.py", line 192, in execute_callable
    return self.python_callable(*self.op_args, **self.op_kwargs)
  File "/opt/airflow/dags/flow.py", line 30, in task_load_path
    raise FileNotFoundError("CSV file not found.")
FileNotFoundError: CSV file not found.
[2025-09-10T07:31:39.017+0000] {taskinstance.py:1323} INFO - Marking task as FAILED. dag_id=csv_validation_pipeline_v1, task_id=load_path_task, execution_date=20250910T072634, start_date=20250910T073138, end_date=20250910T073139
[2025-09-10T07:31:39.031+0000] {standard_task_runner.py:105} ERROR - Failed to execute job 6 for task load_path_task (CSV file not found.; 616)
[2025-09-10T07:31:39.076+0000] {local_task_job.py:208} INFO - Task exited with return code 1
[2025-09-10T07:31:39.110+0000] {taskinstance.py:2578} INFO - 0 downstream tasks scheduled from follow-on schedule check
