[2025-09-15T10:30:05.307+0000] {taskinstance.py:1083} INFO - Dependencies all met for <TaskInstance: csv_metrics_calculator.calculate_metrics manual__2025-09-15T10:29:58.918029+00:00 [queued]>
[2025-09-15T10:30:05.336+0000] {taskinstance.py:1083} INFO - Dependencies all met for <TaskInstance: csv_metrics_calculator.calculate_metrics manual__2025-09-15T10:29:58.918029+00:00 [queued]>
[2025-09-15T10:30:05.337+0000] {taskinstance.py:1279} INFO - 
--------------------------------------------------------------------------------
[2025-09-15T10:30:05.337+0000] {taskinstance.py:1280} INFO - Starting attempt 1 of 1
[2025-09-15T10:30:05.337+0000] {taskinstance.py:1281} INFO - 
--------------------------------------------------------------------------------
[2025-09-15T10:30:05.376+0000] {taskinstance.py:1300} INFO - Executing <Task(PythonOperator): calculate_metrics> on 2025-09-15 10:29:58.918029+00:00
[2025-09-15T10:30:05.392+0000] {standard_task_runner.py:55} INFO - Started process 883 to run task
[2025-09-15T10:30:05.403+0000] {standard_task_runner.py:82} INFO - Running: ['***', 'tasks', 'run', 'csv_metrics_calculator', 'calculate_metrics', 'manual__2025-09-15T10:29:58.918029+00:00', '--job-id', '52', '--raw', '--subdir', 'DAGS_FOLDER/flow.py', '--cfg-path', '/tmp/tmp9zaxn_rp']
[2025-09-15T10:30:05.404+0000] {standard_task_runner.py:83} INFO - Job 52: Subtask calculate_metrics
[2025-09-15T10:30:05.594+0000] {task_command.py:388} INFO - Running <TaskInstance: csv_metrics_calculator.calculate_metrics manual__2025-09-15T10:29:58.918029+00:00 [running]> on host 7b1eb8a59963
[2025-09-15T10:30:05.827+0000] {taskinstance.py:1509} INFO - Exporting the following env vars:
AIRFLOW_CTX_DAG_OWNER=***
AIRFLOW_CTX_DAG_ID=csv_metrics_calculator
AIRFLOW_CTX_TASK_ID=calculate_metrics
AIRFLOW_CTX_EXECUTION_DATE=2025-09-15T10:29:58.918029+00:00
AIRFLOW_CTX_TRY_NUMBER=1
AIRFLOW_CTX_DAG_RUN_ID=manual__2025-09-15T10:29:58.918029+00:00
[2025-09-15T10:30:05.844+0000] {logging_mixin.py:137} INFO - ‚ùå Error reading CSV: [Errno 2] No such file or directory: '/home/jay/login-signup/b.end/uploads/jay.csv'
[2025-09-15T10:30:05.845+0000] {taskinstance.py:1768} ERROR - Task failed with exception
Traceback (most recent call last):
  File "/home/airflow/.local/lib/python3.7/site-packages/airflow/operators/python.py", line 175, in execute
    return_value = self.execute_callable()
  File "/home/airflow/.local/lib/python3.7/site-packages/airflow/operators/python.py", line 192, in execute_callable
    return self.python_callable(*self.op_args, **self.op_kwargs)
  File "/opt/airflow/dags/flow.py", line 12, in calculate_csv_metrics
    df = pd.read_csv(CSV_FILE_PATH)
  File "/home/airflow/.local/lib/python3.7/site-packages/pandas/util/_decorators.py", line 311, in wrapper
    return func(*args, **kwargs)
  File "/home/airflow/.local/lib/python3.7/site-packages/pandas/io/parsers/readers.py", line 586, in read_csv
    return _read(filepath_or_buffer, kwds)
  File "/home/airflow/.local/lib/python3.7/site-packages/pandas/io/parsers/readers.py", line 482, in _read
    parser = TextFileReader(filepath_or_buffer, **kwds)
  File "/home/airflow/.local/lib/python3.7/site-packages/pandas/io/parsers/readers.py", line 811, in __init__
    self._engine = self._make_engine(self.engine)
  File "/home/airflow/.local/lib/python3.7/site-packages/pandas/io/parsers/readers.py", line 1040, in _make_engine
    return mapping[engine](self.f, **self.options)  # type: ignore[call-arg]
  File "/home/airflow/.local/lib/python3.7/site-packages/pandas/io/parsers/c_parser_wrapper.py", line 51, in __init__
    self._open_handles(src, kwds)
  File "/home/airflow/.local/lib/python3.7/site-packages/pandas/io/parsers/base_parser.py", line 229, in _open_handles
    errors=kwds.get("encoding_errors", "strict"),
  File "/home/airflow/.local/lib/python3.7/site-packages/pandas/io/common.py", line 707, in get_handle
    newline="",
FileNotFoundError: [Errno 2] No such file or directory: '/home/jay/login-signup/b.end/uploads/jay.csv'
[2025-09-15T10:30:05.873+0000] {taskinstance.py:1323} INFO - Marking task as FAILED. dag_id=csv_metrics_calculator, task_id=calculate_metrics, execution_date=20250915T102958, start_date=20250915T103005, end_date=20250915T103005
[2025-09-15T10:30:05.916+0000] {standard_task_runner.py:105} ERROR - Failed to execute job 52 for task calculate_metrics ([Errno 2] No such file or directory: '/home/jay/login-signup/b.end/uploads/jay.csv'; 883)
[2025-09-15T10:30:05.979+0000] {local_task_job.py:208} INFO - Task exited with return code 1
[2025-09-15T10:30:06.039+0000] {taskinstance.py:2578} INFO - 0 downstream tasks scheduled from follow-on schedule check
