[2025-09-04T06:40:31.595+0000] {taskinstance.py:1165} INFO - Dependencies all met for <TaskInstance: local_csv_validation_dag.run_local_validation manual__2025-09-04T06:40:28.707284+00:00 [queued]>
[2025-09-04T06:40:31.612+0000] {taskinstance.py:1165} INFO - Dependencies all met for <TaskInstance: local_csv_validation_dag.run_local_validation manual__2025-09-04T06:40:28.707284+00:00 [queued]>
[2025-09-04T06:40:31.613+0000] {taskinstance.py:1362} INFO - 
--------------------------------------------------------------------------------
[2025-09-04T06:40:31.613+0000] {taskinstance.py:1363} INFO - Starting attempt 1 of 1
[2025-09-04T06:40:31.613+0000] {taskinstance.py:1364} INFO - 
--------------------------------------------------------------------------------
[2025-09-04T06:40:31.637+0000] {taskinstance.py:1383} INFO - Executing <Task(PythonOperator): run_local_validation> on 2025-09-04 06:40:28.707284+00:00
[2025-09-04T06:40:31.647+0000] {standard_task_runner.py:55} INFO - Started process 216 to run task
[2025-09-04T06:40:31.653+0000] {standard_task_runner.py:82} INFO - Running: ['***', 'tasks', 'run', 'local_csv_validation_dag', 'run_local_validation', 'manual__2025-09-04T06:40:28.707284+00:00', '--job-id', '3', '--raw', '--subdir', 'DAGS_FOLDER/find_act.py', '--cfg-path', '/tmp/tmp3m7kzz6a']
[2025-09-04T06:40:31.961+0000] {standard_task_runner.py:83} INFO - Job 3: Subtask run_local_validation
[2025-09-04T06:40:32.042+0000] {task_command.py:376} INFO - Running <TaskInstance: local_csv_validation_dag.run_local_validation manual__2025-09-04T06:40:28.707284+00:00 [running]> on host 6789badf8728
[2025-09-04T06:40:32.137+0000] {taskinstance.py:1592} INFO - Exporting the following env vars:
AIRFLOW_CTX_DAG_OWNER=***
AIRFLOW_CTX_DAG_ID=local_csv_validation_dag
AIRFLOW_CTX_TASK_ID=run_local_validation
AIRFLOW_CTX_EXECUTION_DATE=2025-09-04T06:40:28.707284+00:00
AIRFLOW_CTX_TRY_NUMBER=1
AIRFLOW_CTX_DAG_RUN_ID=manual__2025-09-04T06:40:28.707284+00:00
[2025-09-04T06:40:32.138+0000] {taskinstance.py:1851} ERROR - Task failed with exception
Traceback (most recent call last):
  File "/home/airflow/.local/lib/python3.7/site-packages/airflow/operators/python.py", line 175, in execute
    return_value = self.execute_callable()
  File "/home/airflow/.local/lib/python3.7/site-packages/airflow/operators/python.py", line 193, in execute_callable
    return self.python_callable(*self.op_args, **self.op_kwargs)
  File "/opt/airflow/dags/find_act.py", line 32, in run_local_csv_validation
    calculate_metrics(directory)
  File "/opt/airflow/dags/find_act.py", line 14, in calculate_metrics
    raise FileNotFoundError(f"No CSV files found in: {directory}")
FileNotFoundError: No CSV files found in: /opt/***/uploads
[2025-09-04T06:40:32.150+0000] {taskinstance.py:1406} INFO - Marking task as FAILED. dag_id=local_csv_validation_dag, task_id=run_local_validation, execution_date=20250904T064028, start_date=20250904T064031, end_date=20250904T064032
[2025-09-04T06:40:32.165+0000] {standard_task_runner.py:105} ERROR - Failed to execute job 3 for task run_local_validation (No CSV files found in: /opt/***/uploads; 216)
[2025-09-04T06:40:32.227+0000] {local_task_job.py:164} INFO - Task exited with return code 1
[2025-09-04T06:40:32.450+0000] {local_task_job.py:273} INFO - 0 downstream tasks scheduled from follow-on schedule check
