[2025-09-11T10:45:20.958+0000] {taskinstance.py:1083} INFO - Dependencies all met for <TaskInstance: csv_validation_pipeline_v1.load_path_task manual__2025-09-11T10:45:15.956417+00:00 [queued]>
[2025-09-11T10:45:20.975+0000] {taskinstance.py:1083} INFO - Dependencies all met for <TaskInstance: csv_validation_pipeline_v1.load_path_task manual__2025-09-11T10:45:15.956417+00:00 [queued]>
[2025-09-11T10:45:20.976+0000] {taskinstance.py:1279} INFO - 
--------------------------------------------------------------------------------
[2025-09-11T10:45:20.976+0000] {taskinstance.py:1280} INFO - Starting attempt 1 of 2
[2025-09-11T10:45:20.976+0000] {taskinstance.py:1281} INFO - 
--------------------------------------------------------------------------------
[2025-09-11T10:45:20.999+0000] {taskinstance.py:1300} INFO - Executing <Task(PythonOperator): load_path_task> on 2025-09-11 10:45:15.956417+00:00
[2025-09-11T10:45:21.017+0000] {standard_task_runner.py:55} INFO - Started process 274 to run task
[2025-09-11T10:45:21.027+0000] {standard_task_runner.py:82} INFO - Running: ['***', 'tasks', 'run', 'csv_validation_pipeline_v1', 'load_path_task', 'manual__2025-09-11T10:45:15.956417+00:00', '--job-id', '9', '--raw', '--subdir', 'DAGS_FOLDER/flow.py', '--cfg-path', '/tmp/tmpdq_hlnof']
[2025-09-11T10:45:21.031+0000] {standard_task_runner.py:83} INFO - Job 9: Subtask load_path_task
[2025-09-11T10:45:21.149+0000] {task_command.py:388} INFO - Running <TaskInstance: csv_validation_pipeline_v1.load_path_task manual__2025-09-11T10:45:15.956417+00:00 [running]> on host 816aa2f82eb0
[2025-09-11T10:45:21.284+0000] {taskinstance.py:1509} INFO - Exporting the following env vars:
AIRFLOW_CTX_DAG_OWNER=***
AIRFLOW_CTX_DAG_ID=csv_validation_pipeline_v1
AIRFLOW_CTX_TASK_ID=load_path_task
AIRFLOW_CTX_EXECUTION_DATE=2025-09-11T10:45:15.956417+00:00
AIRFLOW_CTX_TRY_NUMBER=1
AIRFLOW_CTX_DAG_RUN_ID=manual__2025-09-11T10:45:15.956417+00:00
[2025-09-11T10:45:21.290+0000] {logging_mixin.py:137} INFO - Checking: /home/jay/login-signup/***_project/uploads/jay.csv
[2025-09-11T10:45:21.291+0000] {logging_mixin.py:137} INFO - Exists? False
[2025-09-11T10:45:21.292+0000] {logging_mixin.py:137} INFO - CSV file not found.
[2025-09-11T10:45:21.292+0000] {taskinstance.py:1768} ERROR - Task failed with exception
Traceback (most recent call last):
  File "/home/airflow/.local/lib/python3.7/site-packages/airflow/operators/python.py", line 175, in execute
    return_value = self.execute_callable()
  File "/home/airflow/.local/lib/python3.7/site-packages/airflow/operators/python.py", line 192, in execute_callable
    return self.python_callable(*self.op_args, **self.op_kwargs)
  File "/opt/airflow/dags/flow.py", line 30, in task_load_path
    raise FileNotFoundError("CSV file not found.")
FileNotFoundError: CSV file not found.
[2025-09-11T10:45:21.308+0000] {taskinstance.py:1323} INFO - Marking task as UP_FOR_RETRY. dag_id=csv_validation_pipeline_v1, task_id=load_path_task, execution_date=20250911T104515, start_date=20250911T104520, end_date=20250911T104521
[2025-09-11T10:45:21.344+0000] {standard_task_runner.py:105} ERROR - Failed to execute job 9 for task load_path_task (CSV file not found.; 274)
[2025-09-11T10:45:21.401+0000] {local_task_job.py:208} INFO - Task exited with return code 1
[2025-09-11T10:45:21.462+0000] {taskinstance.py:2578} INFO - 0 downstream tasks scheduled from follow-on schedule check
