[2025-08-20T18:42:02.196+0000] {taskinstance.py:1165} INFO - Dependencies all met for <TaskInstance: local_csv_validation_dag.run_local_validation manual__2025-08-20T18:35:24.927679+00:00 [queued]>
[2025-08-20T18:42:02.213+0000] {taskinstance.py:1165} INFO - Dependencies all met for <TaskInstance: local_csv_validation_dag.run_local_validation manual__2025-08-20T18:35:24.927679+00:00 [queued]>
[2025-08-20T18:42:02.213+0000] {taskinstance.py:1362} INFO - 
--------------------------------------------------------------------------------
[2025-08-20T18:42:02.214+0000] {taskinstance.py:1363} INFO - Starting attempt 2 of 2
[2025-08-20T18:42:02.214+0000] {taskinstance.py:1364} INFO - 
--------------------------------------------------------------------------------
[2025-08-20T18:42:02.234+0000] {taskinstance.py:1383} INFO - Executing <Task(PythonOperator): run_local_validation> on 2025-08-20 18:35:24.927679+00:00
[2025-08-20T18:42:02.250+0000] {standard_task_runner.py:55} INFO - Started process 82 to run task
[2025-08-20T18:42:02.260+0000] {standard_task_runner.py:82} INFO - Running: ['***', 'tasks', 'run', 'local_csv_validation_dag', 'run_local_validation', 'manual__2025-08-20T18:35:24.927679+00:00', '--job-id', '143', '--raw', '--subdir', 'DAGS_FOLDER/data/csv_validate.py', '--cfg-path', '/tmp/tmpeuycyx44']
[2025-08-20T18:42:02.265+0000] {standard_task_runner.py:83} INFO - Job 143: Subtask run_local_validation
[2025-08-20T18:42:02.838+0000] {task_command.py:376} INFO - Running <TaskInstance: local_csv_validation_dag.run_local_validation manual__2025-08-20T18:35:24.927679+00:00 [running]> on host caf234be515d
[2025-08-20T18:42:02.957+0000] {taskinstance.py:1592} INFO - Exporting the following env vars:
AIRFLOW_CTX_DAG_OWNER=***
AIRFLOW_CTX_DAG_ID=local_csv_validation_dag
AIRFLOW_CTX_TASK_ID=run_local_validation
AIRFLOW_CTX_EXECUTION_DATE=2025-08-20T18:35:24.927679+00:00
AIRFLOW_CTX_TRY_NUMBER=2
AIRFLOW_CTX_DAG_RUN_ID=manual__2025-08-20T18:35:24.927679+00:00
[2025-08-20T18:42:02.963+0000] {taskinstance.py:1851} ERROR - Task failed with exception
Traceback (most recent call last):
  File "/home/airflow/.local/lib/python3.7/site-packages/airflow/operators/python.py", line 175, in execute
    return_value = self.execute_callable()
  File "/home/airflow/.local/lib/python3.7/site-packages/airflow/operators/python.py", line 193, in execute_callable
    return self.python_callable(*self.op_args, **self.op_kwargs)
  File "/opt/airflow/dags/data/csv_validate.py", line 58, in run_local_csv_validation
    calculate_metrics(uploads_dir)
  File "/opt/airflow/dags/data/csv_validate.py", line 28, in calculate_metrics
    raise FileNotFoundError("No CSV files found in directory: " + directory)
NameError: name 'directory' is not defined
[2025-08-20T18:42:02.928+0000] {taskinstance.py:1406} INFO - Marking task as FAILED. dag_id=local_csv_validation_dag, task_id=run_local_validation, execution_date=20250820T183524, start_date=20250820T184202, end_date=20250820T184202
[2025-08-20T18:42:02.957+0000] {standard_task_runner.py:105} ERROR - Failed to execute job 143 for task run_local_validation (name 'directory' is not defined; 82)
[2025-08-20T18:42:03.014+0000] {local_task_job.py:164} INFO - Task exited with return code 1
[2025-08-20T18:42:03.055+0000] {local_task_job.py:273} INFO - 0 downstream tasks scheduled from follow-on schedule check
