[2025-08-20T07:27:59.255+0000] {taskinstance.py:1165} INFO - Dependencies all met for <TaskInstance: csv_validation_dag.run_local_validation manual__2025-08-20T07:22:38.775648+00:00 [queued]>
[2025-08-20T07:27:59.267+0000] {taskinstance.py:1165} INFO - Dependencies all met for <TaskInstance: csv_validation_dag.run_local_validation manual__2025-08-20T07:22:38.775648+00:00 [queued]>
[2025-08-20T07:27:59.267+0000] {taskinstance.py:1362} INFO - 
--------------------------------------------------------------------------------
[2025-08-20T07:27:59.268+0000] {taskinstance.py:1363} INFO - Starting attempt 2 of 2
[2025-08-20T07:27:59.268+0000] {taskinstance.py:1364} INFO - 
--------------------------------------------------------------------------------
[2025-08-20T07:27:59.299+0000] {taskinstance.py:1383} INFO - Executing <Task(PythonOperator): run_local_validation> on 2025-08-20 07:22:38.775648+00:00
[2025-08-20T07:27:59.311+0000] {standard_task_runner.py:55} INFO - Started process 90 to run task
[2025-08-20T07:27:59.316+0000] {standard_task_runner.py:82} INFO - Running: ['***', 'tasks', 'run', 'csv_validation_dag', 'run_local_validation', 'manual__2025-08-20T07:22:38.775648+00:00', '--job-id', '129', '--raw', '--subdir', 'DAGS_FOLDER/find_act.py', '--cfg-path', '/tmp/tmp2vwaj9um']
[2025-08-20T07:27:59.570+0000] {standard_task_runner.py:83} INFO - Job 129: Subtask run_local_validation
[2025-08-20T07:27:59.647+0000] {task_command.py:376} INFO - Running <TaskInstance: csv_validation_dag.run_local_validation manual__2025-08-20T07:22:38.775648+00:00 [running]> on host 5a212e308420
[2025-08-20T07:27:59.727+0000] {taskinstance.py:1592} INFO - Exporting the following env vars:
AIRFLOW_CTX_DAG_OWNER=***
AIRFLOW_CTX_DAG_ID=csv_validation_dag
AIRFLOW_CTX_TASK_ID=run_local_validation
AIRFLOW_CTX_EXECUTION_DATE=2025-08-20T07:22:38.775648+00:00
AIRFLOW_CTX_TRY_NUMBER=2
AIRFLOW_CTX_DAG_RUN_ID=manual__2025-08-20T07:22:38.775648+00:00
[2025-08-20T07:27:59.729+0000] {taskinstance.py:1851} ERROR - Task failed with exception
Traceback (most recent call last):
  File "/home/airflow/.local/lib/python3.7/site-packages/airflow/operators/python.py", line 175, in execute
    return_value = self.execute_callable()
  File "/home/airflow/.local/lib/python3.7/site-packages/airflow/operators/python.py", line 193, in execute_callable
    return self.python_callable(*self.op_args, **self.op_kwargs)
  File "/opt/airflow/dags/find_act.py", line 56, in run_local_csv_validation
    calculate_metrics(uploads_dir)
  File "/opt/airflow/dags/find_act.py", line 28, in calculate_metrics
    raise FileNotFoundError(f"No CSV files found in directory: {directory}")
FileNotFoundError: No CSV files found in directory: /home/jay/login-signup/uploads
[2025-08-20T07:27:59.740+0000] {taskinstance.py:1406} INFO - Marking task as FAILED. dag_id=csv_validation_dag, task_id=run_local_validation, execution_date=20250820T072238, start_date=20250820T072759, end_date=20250820T072759
[2025-08-20T07:27:59.752+0000] {standard_task_runner.py:105} ERROR - Failed to execute job 129 for task run_local_validation (No CSV files found in directory: /home/jay/login-signup/uploads; 90)
[2025-08-20T07:27:59.769+0000] {local_task_job.py:164} INFO - Task exited with return code 1
[2025-08-20T07:28:00.014+0000] {local_task_job.py:273} INFO - 0 downstream tasks scheduled from follow-on schedule check
