[2025-08-20T18:47:04.600+0000] {taskinstance.py:1165} INFO - Dependencies all met for <TaskInstance: local_csv_validation_dag.run_local_validation manual__2025-08-20T18:42:00.661218+00:00 [queued]>
[2025-08-20T18:47:04.609+0000] {taskinstance.py:1165} INFO - Dependencies all met for <TaskInstance: local_csv_validation_dag.run_local_validation manual__2025-08-20T18:42:00.661218+00:00 [queued]>
[2025-08-20T18:47:04.609+0000] {taskinstance.py:1362} INFO - 
--------------------------------------------------------------------------------
[2025-08-20T18:47:04.609+0000] {taskinstance.py:1363} INFO - Starting attempt 2 of 2
[2025-08-20T18:47:04.609+0000] {taskinstance.py:1364} INFO - 
--------------------------------------------------------------------------------
[2025-08-20T18:47:04.620+0000] {taskinstance.py:1383} INFO - Executing <Task(PythonOperator): run_local_validation> on 2025-08-20 18:42:00.661218+00:00
[2025-08-20T18:47:04.627+0000] {standard_task_runner.py:55} INFO - Started process 116 to run task
[2025-08-20T18:47:04.631+0000] {standard_task_runner.py:82} INFO - Running: ['***', 'tasks', 'run', 'local_csv_validation_dag', 'run_local_validation', 'manual__2025-08-20T18:42:00.661218+00:00', '--job-id', '147', '--raw', '--subdir', 'DAGS_FOLDER/find_act.py', '--cfg-path', '/tmp/tmpe6yr3awr']
[2025-08-20T18:47:04.633+0000] {standard_task_runner.py:83} INFO - Job 147: Subtask run_local_validation
[2025-08-20T18:47:04.882+0000] {task_command.py:376} INFO - Running <TaskInstance: local_csv_validation_dag.run_local_validation manual__2025-08-20T18:42:00.661218+00:00 [running]> on host caf234be515d
[2025-08-20T18:47:04.938+0000] {taskinstance.py:1592} INFO - Exporting the following env vars:
AIRFLOW_CTX_DAG_OWNER=***
AIRFLOW_CTX_DAG_ID=local_csv_validation_dag
AIRFLOW_CTX_TASK_ID=run_local_validation
AIRFLOW_CTX_EXECUTION_DATE=2025-08-20T18:42:00.661218+00:00
AIRFLOW_CTX_TRY_NUMBER=2
AIRFLOW_CTX_DAG_RUN_ID=manual__2025-08-20T18:42:00.661218+00:00
[2025-08-20T18:47:04.939+0000] {taskinstance.py:1851} ERROR - Task failed with exception
Traceback (most recent call last):
  File "/home/airflow/.local/lib/python3.7/site-packages/airflow/operators/python.py", line 175, in execute
    return_value = self.execute_callable()
  File "/home/airflow/.local/lib/python3.7/site-packages/airflow/operators/python.py", line 193, in execute_callable
    return self.python_callable(*self.op_args, **self.op_kwargs)
  File "/opt/airflow/dags/find_act.py", line 29, in run_local_csv_validation
    calculate_metrics(op_args)
  File "/opt/airflow/dags/find_act.py", line 13, in calculate_metrics
    latest_csv = max(csv_files, key=os.path.getmtime)
ValueError: max() arg is an empty sequence
[2025-08-20T18:47:04.946+0000] {taskinstance.py:1406} INFO - Marking task as FAILED. dag_id=local_csv_validation_dag, task_id=run_local_validation, execution_date=20250820T184200, start_date=20250820T184704, end_date=20250820T184704
[2025-08-20T18:47:04.957+0000] {standard_task_runner.py:105} ERROR - Failed to execute job 147 for task run_local_validation (max() arg is an empty sequence; 116)
[2025-08-20T18:47:05.002+0000] {local_task_job.py:164} INFO - Task exited with return code 1
[2025-08-20T18:47:05.019+0000] {local_task_job.py:273} INFO - 0 downstream tasks scheduled from follow-on schedule check
