[2025-09-04T08:32:45.906+0000] {taskinstance.py:1165} INFO - Dependencies all met for <TaskInstance: local_csv_validation_dag.run_local_validation manual__2025-09-04T08:32:42.614916+00:00 [queued]>
[2025-09-04T08:32:45.927+0000] {taskinstance.py:1165} INFO - Dependencies all met for <TaskInstance: local_csv_validation_dag.run_local_validation manual__2025-09-04T08:32:42.614916+00:00 [queued]>
[2025-09-04T08:32:45.927+0000] {taskinstance.py:1362} INFO - 
--------------------------------------------------------------------------------
[2025-09-04T08:32:45.928+0000] {taskinstance.py:1363} INFO - Starting attempt 1 of 1
[2025-09-04T08:32:45.928+0000] {taskinstance.py:1364} INFO - 
--------------------------------------------------------------------------------
[2025-09-04T08:32:45.952+0000] {taskinstance.py:1383} INFO - Executing <Task(PythonOperator): run_local_validation> on 2025-09-04 08:32:42.614916+00:00
[2025-09-04T08:32:45.962+0000] {standard_task_runner.py:55} INFO - Started process 616 to run task
[2025-09-04T08:32:45.967+0000] {standard_task_runner.py:82} INFO - Running: ['***', 'tasks', 'run', 'local_csv_validation_dag', 'run_local_validation', 'manual__2025-09-04T08:32:42.614916+00:00', '--job-id', '16', '--raw', '--subdir', 'DAGS_FOLDER/data/csv_validate.py', '--cfg-path', '/tmp/tmpctkge_yu']
[2025-09-04T08:32:47.077+0000] {standard_task_runner.py:83} INFO - Job 16: Subtask run_local_validation
[2025-09-04T08:32:47.130+0000] {task_command.py:376} INFO - Running <TaskInstance: local_csv_validation_dag.run_local_validation manual__2025-09-04T08:32:42.614916+00:00 [running]> on host e1c117c7bd96
[2025-09-04T08:32:47.195+0000] {taskinstance.py:1592} INFO - Exporting the following env vars:
AIRFLOW_CTX_DAG_OWNER=***
AIRFLOW_CTX_DAG_ID=local_csv_validation_dag
AIRFLOW_CTX_TASK_ID=run_local_validation
AIRFLOW_CTX_EXECUTION_DATE=2025-09-04T08:32:42.614916+00:00
AIRFLOW_CTX_TRY_NUMBER=1
AIRFLOW_CTX_DAG_RUN_ID=manual__2025-09-04T08:32:42.614916+00:00
[2025-09-04T08:32:47.196+0000] {taskinstance.py:1851} ERROR - Task failed with exception
Traceback (most recent call last):
  File "/home/airflow/.local/lib/python3.7/site-packages/airflow/operators/python.py", line 175, in execute
    return_value = self.execute_callable()
  File "/home/airflow/.local/lib/python3.7/site-packages/airflow/operators/python.py", line 193, in execute_callable
    return self.python_callable(*self.op_args, **self.op_kwargs)
  File "/opt/airflow/dags/data/csv_validate.py", line 58, in run_local_csv_validation
    calculate_metrics(uploads_dir)
  File "/opt/airflow/dags/data/csv_validate.py", line 28, in calculate_metrics
    raise FileNotFoundError("No CSV files found in directory: " + directory)
NameError: name 'directory' is not defined
[2025-09-04T08:32:47.205+0000] {taskinstance.py:1406} INFO - Marking task as FAILED. dag_id=local_csv_validation_dag, task_id=run_local_validation, execution_date=20250904T083242, start_date=20250904T083245, end_date=20250904T083247
[2025-09-04T08:32:47.221+0000] {standard_task_runner.py:105} ERROR - Failed to execute job 16 for task run_local_validation (name 'directory' is not defined; 616)
[2025-09-04T08:32:47.268+0000] {local_task_job.py:164} INFO - Task exited with return code 1
[2025-09-04T08:32:47.448+0000] {local_task_job.py:273} INFO - 0 downstream tasks scheduled from follow-on schedule check
